[2024-05-20T17:03:43.975+0000] {local_task_job_runner.py:120} INFO - ::group::Pre task execution logs
[2024-05-20T17:03:43.982+0000] {taskinstance.py:2076} INFO - Dependencies all met for dep_context=non-requeueable deps ti=<TaskInstance: weather_dag.transform_load_weather_data manual__2024-05-20T17:01:37.927269+00:00 [queued]>
[2024-05-20T17:03:43.986+0000] {taskinstance.py:2076} INFO - Dependencies all met for dep_context=requeueable deps ti=<TaskInstance: weather_dag.transform_load_weather_data manual__2024-05-20T17:01:37.927269+00:00 [queued]>
[2024-05-20T17:03:43.986+0000] {taskinstance.py:2306} INFO - Starting attempt 2 of 3
[2024-05-20T17:03:43.991+0000] {taskinstance.py:2330} INFO - Executing <Task(PythonOperator): transform_load_weather_data> on 2024-05-20 17:01:37.927269+00:00
[2024-05-20T17:03:43.995+0000] {warnings.py:110} WARNING - /home/***/.local/lib/python3.12/site-packages/***/task/task_runner/standard_task_runner.py:61: DeprecationWarning: This process (pid=4779) is multi-threaded, use of fork() may lead to deadlocks in the child.
  pid = os.fork()

[2024-05-20T17:03:43.996+0000] {standard_task_runner.py:63} INFO - Started process 4781 to run task
[2024-05-20T17:03:43.996+0000] {standard_task_runner.py:90} INFO - Running: ['***', 'tasks', 'run', 'weather_dag', 'transform_load_weather_data', 'manual__2024-05-20T17:01:37.927269+00:00', '--job-id', '18', '--raw', '--subdir', 'DAGS_FOLDER/weather_dag.py', '--cfg-path', '/tmp/tmpxzq7n9rk']
[2024-05-20T17:03:43.997+0000] {standard_task_runner.py:91} INFO - Job 18: Subtask transform_load_weather_data
[2024-05-20T17:03:44.018+0000] {task_command.py:426} INFO - Running <TaskInstance: weather_dag.transform_load_weather_data manual__2024-05-20T17:01:37.927269+00:00 [running]> on host 39024998a807
[2024-05-20T17:03:44.059+0000] {taskinstance.py:2648} INFO - Exporting env vars: AIRFLOW_CTX_DAG_OWNER='***' AIRFLOW_CTX_DAG_ID='weather_dag' AIRFLOW_CTX_TASK_ID='transform_load_weather_data' AIRFLOW_CTX_EXECUTION_DATE='2024-05-20T17:01:37.927269+00:00' AIRFLOW_CTX_TRY_NUMBER='2' AIRFLOW_CTX_DAG_RUN_ID='manual__2024-05-20T17:01:37.927269+00:00'
[2024-05-20T17:03:44.060+0000] {taskinstance.py:430} INFO - ::endgroup::
[2024-05-20T17:03:44.068+0000] {taskinstance.py:441} INFO - ::group::Post task execution logs
[2024-05-20T17:03:44.068+0000] {taskinstance.py:2905} ERROR - Task failed with exception
Traceback (most recent call last):
  File "/home/airflow/.local/lib/python3.12/site-packages/airflow/models/taskinstance.py", line 465, in _execute_task
    result = _execute_callable(context=context, **execute_callable_kwargs)
             ^^^^^^^^^^^^^^^^^^^^^^^^^^^^^^^^^^^^^^^^^^^^^^^^^^^^^^^^^^^^^
  File "/home/airflow/.local/lib/python3.12/site-packages/airflow/models/taskinstance.py", line 432, in _execute_callable
    return execute_callable(context=context, **execute_callable_kwargs)
           ^^^^^^^^^^^^^^^^^^^^^^^^^^^^^^^^^^^^^^^^^^^^^^^^^^^^^^^^^^^^
  File "/home/airflow/.local/lib/python3.12/site-packages/airflow/models/baseoperator.py", line 400, in wrapper
    return func(self, *args, **kwargs)
           ^^^^^^^^^^^^^^^^^^^^^^^^^^^
  File "/home/airflow/.local/lib/python3.12/site-packages/airflow/operators/python.py", line 235, in execute
    return_value = self.execute_callable()
                   ^^^^^^^^^^^^^^^^^^^^^^^
  File "/home/airflow/.local/lib/python3.12/site-packages/airflow/operators/python.py", line 252, in execute_callable
    return self.python_callable(*self.op_args, **self.op_kwargs)
           ^^^^^^^^^^^^^^^^^^^^^^^^^^^^^^^^^^^^^^^^^^^^^^^^^^^^^
  File "/opt/airflow/dags/weather_dag.py", line 50, in transform_load_data
    df_data.to_csv(f"/workspaces/airflow_docker_setup/{dt_string}.csv", index=False)
  File "/home/airflow/.local/lib/python3.12/site-packages/pandas/core/generic.py", line 3902, in to_csv
    return DataFrameRenderer(formatter).to_csv(
           ^^^^^^^^^^^^^^^^^^^^^^^^^^^^^^^^^^^^
  File "/home/airflow/.local/lib/python3.12/site-packages/pandas/io/formats/format.py", line 1152, in to_csv
    csv_formatter.save()
  File "/home/airflow/.local/lib/python3.12/site-packages/pandas/io/formats/csvs.py", line 247, in save
    with get_handle(
         ^^^^^^^^^^^
  File "/home/airflow/.local/lib/python3.12/site-packages/pandas/io/common.py", line 739, in get_handle
    check_parent_directory(str(handle))
  File "/home/airflow/.local/lib/python3.12/site-packages/pandas/io/common.py", line 604, in check_parent_directory
    raise OSError(rf"Cannot save file into a non-existent directory: '{parent}'")
OSError: Cannot save file into a non-existent directory: '/workspaces/***_docker_setup'
[2024-05-20T17:03:44.076+0000] {taskinstance.py:1206} INFO - Marking task as UP_FOR_RETRY. dag_id=weather_dag, task_id=transform_load_weather_data, run_id=manual__2024-05-20T17:01:37.927269+00:00, execution_date=20240520T170137, start_date=20240520T170343, end_date=20240520T170344
[2024-05-20T17:03:44.081+0000] {standard_task_runner.py:110} ERROR - Failed to execute job 18 for task transform_load_weather_data (Cannot save file into a non-existent directory: '/workspaces/***_docker_setup'; 4781)
[2024-05-20T17:03:44.098+0000] {local_task_job_runner.py:240} INFO - Task exited with return code 1
[2024-05-20T17:03:44.105+0000] {taskinstance.py:3498} INFO - 0 downstream tasks scheduled from follow-on schedule check
[2024-05-20T17:03:44.106+0000] {local_task_job_runner.py:222} INFO - ::endgroup::
