[2024-05-21T05:04:27.603+0000] {local_task_job_runner.py:120} INFO - ::group::Pre task execution logs
[2024-05-21T05:04:27.611+0000] {taskinstance.py:2076} INFO - Dependencies all met for dep_context=non-requeueable deps ti=<TaskInstance: weather_dag.push_to_s3 manual__2024-05-21T05:04:21.186130+00:00 [queued]>
[2024-05-21T05:04:27.614+0000] {taskinstance.py:2076} INFO - Dependencies all met for dep_context=requeueable deps ti=<TaskInstance: weather_dag.push_to_s3 manual__2024-05-21T05:04:21.186130+00:00 [queued]>
[2024-05-21T05:04:27.614+0000] {taskinstance.py:2306} INFO - Starting attempt 1 of 3
[2024-05-21T05:04:27.619+0000] {taskinstance.py:2330} INFO - Executing <Task(PythonOperator): push_to_s3> on 2024-05-21 05:04:21.186130+00:00
[2024-05-21T05:04:27.622+0000] {warnings.py:110} WARNING - /home/***/.local/lib/python3.12/site-packages/***/task/task_runner/standard_task_runner.py:61: DeprecationWarning: This process (pid=8061) is multi-threaded, use of fork() may lead to deadlocks in the child.
  pid = os.fork()

[2024-05-21T05:04:27.623+0000] {standard_task_runner.py:63} INFO - Started process 8063 to run task
[2024-05-21T05:04:27.624+0000] {standard_task_runner.py:90} INFO - Running: ['***', 'tasks', 'run', 'weather_dag', 'push_to_s3', 'manual__2024-05-21T05:04:21.186130+00:00', '--job-id', '91', '--raw', '--subdir', 'DAGS_FOLDER/weather_dag.py', '--cfg-path', '/tmp/tmp2mm4ku6g']
[2024-05-21T05:04:27.624+0000] {standard_task_runner.py:91} INFO - Job 91: Subtask push_to_s3
[2024-05-21T05:04:27.645+0000] {task_command.py:426} INFO - Running <TaskInstance: weather_dag.push_to_s3 manual__2024-05-21T05:04:21.186130+00:00 [running]> on host 39024998a807
[2024-05-21T05:04:27.684+0000] {taskinstance.py:2648} INFO - Exporting env vars: AIRFLOW_CTX_DAG_OWNER='***' AIRFLOW_CTX_DAG_ID='weather_dag' AIRFLOW_CTX_TASK_ID='push_to_s3' AIRFLOW_CTX_EXECUTION_DATE='2024-05-21T05:04:21.186130+00:00' AIRFLOW_CTX_TRY_NUMBER='1' AIRFLOW_CTX_DAG_RUN_ID='manual__2024-05-21T05:04:21.186130+00:00'
[2024-05-21T05:04:27.685+0000] {taskinstance.py:430} INFO - ::endgroup::
[2024-05-21T05:04:27.759+0000] {taskinstance.py:441} INFO - ::group::Post task execution logs
[2024-05-21T05:04:27.760+0000] {taskinstance.py:2905} ERROR - Task failed with exception
Traceback (most recent call last):
  File "/home/airflow/.local/lib/python3.12/site-packages/airflow/models/taskinstance.py", line 465, in _execute_task
    result = _execute_callable(context=context, **execute_callable_kwargs)
             ^^^^^^^^^^^^^^^^^^^^^^^^^^^^^^^^^^^^^^^^^^^^^^^^^^^^^^^^^^^^^
  File "/home/airflow/.local/lib/python3.12/site-packages/airflow/models/taskinstance.py", line 432, in _execute_callable
    return execute_callable(context=context, **execute_callable_kwargs)
           ^^^^^^^^^^^^^^^^^^^^^^^^^^^^^^^^^^^^^^^^^^^^^^^^^^^^^^^^^^^^
  File "/home/airflow/.local/lib/python3.12/site-packages/airflow/models/baseoperator.py", line 400, in wrapper
    return func(self, *args, **kwargs)
           ^^^^^^^^^^^^^^^^^^^^^^^^^^^
  File "/home/airflow/.local/lib/python3.12/site-packages/airflow/operators/python.py", line 235, in execute
    return_value = self.execute_callable()
                   ^^^^^^^^^^^^^^^^^^^^^^^
  File "/home/airflow/.local/lib/python3.12/site-packages/airflow/operators/python.py", line 252, in execute_callable
    return self.python_callable(*self.op_args, **self.op_kwargs)
           ^^^^^^^^^^^^^^^^^^^^^^^^^^^^^^^^^^^^^^^^^^^^^^^^^^^^^
  File "/opt/airflow/dags/weather_dag.py", line 14, in pushS3
    with open(f"/opt/airflow/logs/{dt_string}.csv","rb") as f:
                                   ^^^^^^^^^
NameError: name 'dt_string' is not defined
[2024-05-21T05:04:27.767+0000] {taskinstance.py:1206} INFO - Marking task as UP_FOR_RETRY. dag_id=weather_dag, task_id=push_to_s3, run_id=manual__2024-05-21T05:04:21.186130+00:00, execution_date=20240521T050421, start_date=20240521T050427, end_date=20240521T050427
[2024-05-21T05:04:27.772+0000] {standard_task_runner.py:110} ERROR - Failed to execute job 91 for task push_to_s3 (name 'dt_string' is not defined; 8063)
[2024-05-21T05:04:27.806+0000] {local_task_job_runner.py:240} INFO - Task exited with return code 1
[2024-05-21T05:04:27.815+0000] {taskinstance.py:3498} INFO - 0 downstream tasks scheduled from follow-on schedule check
[2024-05-21T05:04:27.816+0000] {local_task_job_runner.py:222} INFO - ::endgroup::
