[2024-05-22T03:34:59.788+0000] {local_task_job_runner.py:120} INFO - ::group::Pre task execution logs
[2024-05-22T03:34:59.795+0000] {taskinstance.py:2076} INFO - Dependencies all met for dep_context=non-requeueable deps ti=<TaskInstance: weather_dag.transform_load_weather_data scheduled__2024-05-21T00:00:00+00:00 [queued]>
[2024-05-22T03:34:59.798+0000] {taskinstance.py:2076} INFO - Dependencies all met for dep_context=requeueable deps ti=<TaskInstance: weather_dag.transform_load_weather_data scheduled__2024-05-21T00:00:00+00:00 [queued]>
[2024-05-22T03:34:59.798+0000] {taskinstance.py:2306} INFO - Starting attempt 2 of 3
[2024-05-22T03:34:59.804+0000] {taskinstance.py:2330} INFO - Executing <Task(PythonOperator): transform_load_weather_data> on 2024-05-21 00:00:00+00:00
[2024-05-22T03:34:59.807+0000] {warnings.py:110} WARNING - /home/***/.local/lib/python3.12/site-packages/***/task/task_runner/standard_task_runner.py:61: DeprecationWarning: This process (pid=84) is multi-threaded, use of fork() may lead to deadlocks in the child.
  pid = os.fork()

[2024-05-22T03:34:59.807+0000] {standard_task_runner.py:63} INFO - Started process 86 to run task
[2024-05-22T03:34:59.808+0000] {standard_task_runner.py:90} INFO - Running: ['***', 'tasks', 'run', 'weather_dag', 'transform_load_weather_data', 'scheduled__2024-05-21T00:00:00+00:00', '--job-id', '128', '--raw', '--subdir', 'DAGS_FOLDER/weather_dag.py', '--cfg-path', '/tmp/tmpbh58s35d']
[2024-05-22T03:34:59.809+0000] {standard_task_runner.py:91} INFO - Job 128: Subtask transform_load_weather_data
[2024-05-22T03:34:59.829+0000] {task_command.py:426} INFO - Running <TaskInstance: weather_dag.transform_load_weather_data scheduled__2024-05-21T00:00:00+00:00 [running]> on host 39024998a807
[2024-05-22T03:34:59.868+0000] {taskinstance.py:2648} INFO - Exporting env vars: AIRFLOW_CTX_DAG_OWNER='***' AIRFLOW_CTX_DAG_ID='weather_dag' AIRFLOW_CTX_TASK_ID='transform_load_weather_data' AIRFLOW_CTX_EXECUTION_DATE='2024-05-21T00:00:00+00:00' AIRFLOW_CTX_TRY_NUMBER='2' AIRFLOW_CTX_DAG_RUN_ID='scheduled__2024-05-21T00:00:00+00:00'
[2024-05-22T03:34:59.868+0000] {taskinstance.py:430} INFO - ::endgroup::
[2024-05-22T03:35:00.914+0000] {taskinstance.py:441} INFO - ::group::Post task execution logs
[2024-05-22T03:35:00.915+0000] {taskinstance.py:2905} ERROR - Task failed with exception
Traceback (most recent call last):
  File "/home/airflow/.local/lib/python3.12/site-packages/airflow/models/taskinstance.py", line 465, in _execute_task
    result = _execute_callable(context=context, **execute_callable_kwargs)
             ^^^^^^^^^^^^^^^^^^^^^^^^^^^^^^^^^^^^^^^^^^^^^^^^^^^^^^^^^^^^^
  File "/home/airflow/.local/lib/python3.12/site-packages/airflow/models/taskinstance.py", line 432, in _execute_callable
    return execute_callable(context=context, **execute_callable_kwargs)
           ^^^^^^^^^^^^^^^^^^^^^^^^^^^^^^^^^^^^^^^^^^^^^^^^^^^^^^^^^^^^
  File "/home/airflow/.local/lib/python3.12/site-packages/airflow/models/baseoperator.py", line 400, in wrapper
    return func(self, *args, **kwargs)
           ^^^^^^^^^^^^^^^^^^^^^^^^^^^
  File "/home/airflow/.local/lib/python3.12/site-packages/airflow/operators/python.py", line 235, in execute
    return_value = self.execute_callable()
                   ^^^^^^^^^^^^^^^^^^^^^^^
  File "/home/airflow/.local/lib/python3.12/site-packages/airflow/operators/python.py", line 252, in execute_callable
    return self.python_callable(*self.op_args, **self.op_kwargs)
           ^^^^^^^^^^^^^^^^^^^^^^^^^^^^^^^^^^^^^^^^^^^^^^^^^^^^^
  File "/opt/airflow/dags/weather_dag.py", line 78, in transform_load_data
    client.put_object(Bucket=bucket_name, Key=dt_string, Body=csv_string.getvalue())
  File "/home/airflow/.local/lib/python3.12/site-packages/botocore/client.py", line 553, in _api_call
    return self._make_api_call(operation_name, kwargs)
           ^^^^^^^^^^^^^^^^^^^^^^^^^^^^^^^^^^^^^^^^^^^
  File "/home/airflow/.local/lib/python3.12/site-packages/botocore/client.py", line 1009, in _make_api_call
    raise error_class(parsed_response, operation_name)
botocore.errorfactory.NoSuchBucket: An error occurred (NoSuchBucket) when calling the PutObject operation: The specified bucket does not exist
[2024-05-22T03:35:00.929+0000] {taskinstance.py:1206} INFO - Marking task as UP_FOR_RETRY. dag_id=weather_dag, task_id=transform_load_weather_data, run_id=scheduled__2024-05-21T00:00:00+00:00, execution_date=20240521T000000, start_date=20240522T033459, end_date=20240522T033500
[2024-05-22T03:35:00.936+0000] {standard_task_runner.py:110} ERROR - Failed to execute job 128 for task transform_load_weather_data (An error occurred (NoSuchBucket) when calling the PutObject operation: The specified bucket does not exist; 86)
[2024-05-22T03:35:00.960+0000] {local_task_job_runner.py:240} INFO - Task exited with return code 1
[2024-05-22T03:35:00.976+0000] {taskinstance.py:3498} INFO - 0 downstream tasks scheduled from follow-on schedule check
[2024-05-22T03:35:00.977+0000] {local_task_job_runner.py:222} INFO - ::endgroup::
