[2024-05-20T18:35:24.867+0000] {local_task_job_runner.py:120} INFO - ::group::Pre task execution logs
[2024-05-20T18:35:24.874+0000] {taskinstance.py:2076} INFO - Dependencies all met for dep_context=non-requeueable deps ti=<TaskInstance: weather_dag.transform_load_weather_data manual__2024-05-20T18:30:21.431375+00:00 [queued]>
[2024-05-20T18:35:24.878+0000] {taskinstance.py:2076} INFO - Dependencies all met for dep_context=requeueable deps ti=<TaskInstance: weather_dag.transform_load_weather_data manual__2024-05-20T18:30:21.431375+00:00 [queued]>
[2024-05-20T18:35:24.878+0000] {taskinstance.py:2306} INFO - Starting attempt 3 of 3
[2024-05-20T18:35:24.884+0000] {taskinstance.py:2330} INFO - Executing <Task(PythonOperator): transform_load_weather_data> on 2024-05-20 18:30:21.431375+00:00
[2024-05-20T18:35:24.887+0000] {warnings.py:110} WARNING - /home/***/.local/lib/python3.12/site-packages/***/task/task_runner/standard_task_runner.py:61: DeprecationWarning: This process (pid=5988) is multi-threaded, use of fork() may lead to deadlocks in the child.
  pid = os.fork()

[2024-05-20T18:35:24.888+0000] {standard_task_runner.py:63} INFO - Started process 5990 to run task
[2024-05-20T18:35:24.888+0000] {standard_task_runner.py:90} INFO - Running: ['***', 'tasks', 'run', 'weather_dag', 'transform_load_weather_data', 'manual__2024-05-20T18:30:21.431375+00:00', '--job-id', '27', '--raw', '--subdir', 'DAGS_FOLDER/weather_dag.py', '--cfg-path', '/tmp/tmpv_bjx8qr']
[2024-05-20T18:35:24.889+0000] {standard_task_runner.py:91} INFO - Job 27: Subtask transform_load_weather_data
[2024-05-20T18:35:24.911+0000] {task_command.py:426} INFO - Running <TaskInstance: weather_dag.transform_load_weather_data manual__2024-05-20T18:30:21.431375+00:00 [running]> on host 39024998a807
[2024-05-20T18:35:24.949+0000] {taskinstance.py:2648} INFO - Exporting env vars: AIRFLOW_CTX_DAG_OWNER='***' AIRFLOW_CTX_DAG_ID='weather_dag' AIRFLOW_CTX_TASK_ID='transform_load_weather_data' AIRFLOW_CTX_EXECUTION_DATE='2024-05-20T18:30:21.431375+00:00' AIRFLOW_CTX_TRY_NUMBER='3' AIRFLOW_CTX_DAG_RUN_ID='manual__2024-05-20T18:30:21.431375+00:00'
[2024-05-20T18:35:24.950+0000] {taskinstance.py:430} INFO - ::endgroup::
[2024-05-20T18:35:24.959+0000] {taskinstance.py:441} INFO - ::group::Post task execution logs
[2024-05-20T18:35:24.959+0000] {taskinstance.py:2905} ERROR - Task failed with exception
Traceback (most recent call last):
  File "/home/airflow/.local/lib/python3.12/site-packages/airflow/models/taskinstance.py", line 465, in _execute_task
    result = _execute_callable(context=context, **execute_callable_kwargs)
             ^^^^^^^^^^^^^^^^^^^^^^^^^^^^^^^^^^^^^^^^^^^^^^^^^^^^^^^^^^^^^
  File "/home/airflow/.local/lib/python3.12/site-packages/airflow/models/taskinstance.py", line 432, in _execute_callable
    return execute_callable(context=context, **execute_callable_kwargs)
           ^^^^^^^^^^^^^^^^^^^^^^^^^^^^^^^^^^^^^^^^^^^^^^^^^^^^^^^^^^^^
  File "/home/airflow/.local/lib/python3.12/site-packages/airflow/models/baseoperator.py", line 400, in wrapper
    return func(self, *args, **kwargs)
           ^^^^^^^^^^^^^^^^^^^^^^^^^^^
  File "/home/airflow/.local/lib/python3.12/site-packages/airflow/operators/python.py", line 235, in execute
    return_value = self.execute_callable()
                   ^^^^^^^^^^^^^^^^^^^^^^^
  File "/home/airflow/.local/lib/python3.12/site-packages/airflow/operators/python.py", line 252, in execute_callable
    return self.python_callable(*self.op_args, **self.op_kwargs)
           ^^^^^^^^^^^^^^^^^^^^^^^^^^^^^^^^^^^^^^^^^^^^^^^^^^^^^
  File "/opt/airflow/dags/weather_dag.py", line 50, in transform_load_data
    df_data.to_csv(f"/{dt_string}.csv", index=False)
  File "/home/airflow/.local/lib/python3.12/site-packages/pandas/core/generic.py", line 3902, in to_csv
    return DataFrameRenderer(formatter).to_csv(
           ^^^^^^^^^^^^^^^^^^^^^^^^^^^^^^^^^^^^
  File "/home/airflow/.local/lib/python3.12/site-packages/pandas/io/formats/format.py", line 1152, in to_csv
    csv_formatter.save()
  File "/home/airflow/.local/lib/python3.12/site-packages/pandas/io/formats/csvs.py", line 247, in save
    with get_handle(
         ^^^^^^^^^^^
  File "/home/airflow/.local/lib/python3.12/site-packages/pandas/io/common.py", line 863, in get_handle
    handle = open(
             ^^^^^
PermissionError: [Errno 13] Permission denied: '/current_weather_data_portland_20052024183524.csv'
[2024-05-20T18:35:24.966+0000] {taskinstance.py:1206} INFO - Marking task as FAILED. dag_id=weather_dag, task_id=transform_load_weather_data, run_id=manual__2024-05-20T18:30:21.431375+00:00, execution_date=20240520T183021, start_date=20240520T183524, end_date=20240520T183524
[2024-05-20T18:35:24.972+0000] {standard_task_runner.py:110} ERROR - Failed to execute job 27 for task transform_load_weather_data ([Errno 13] Permission denied: '/current_weather_data_portland_20052024183524.csv'; 5990)
[2024-05-20T18:35:24.986+0000] {local_task_job_runner.py:240} INFO - Task exited with return code 1
[2024-05-20T18:35:24.996+0000] {taskinstance.py:3498} INFO - 0 downstream tasks scheduled from follow-on schedule check
[2024-05-20T18:35:24.997+0000] {local_task_job_runner.py:222} INFO - ::endgroup::
