[2024-05-21T04:45:20.746+0000] {local_task_job_runner.py:120} INFO - ::group::Pre task execution logs
[2024-05-21T04:45:20.754+0000] {taskinstance.py:2076} INFO - Dependencies all met for dep_context=non-requeueable deps ti=<TaskInstance: weather_dag.transform_load_weather_data manual__2024-05-21T04:41:11.953754+00:00 [queued]>
[2024-05-21T04:45:20.758+0000] {taskinstance.py:2076} INFO - Dependencies all met for dep_context=requeueable deps ti=<TaskInstance: weather_dag.transform_load_weather_data manual__2024-05-21T04:41:11.953754+00:00 [queued]>
[2024-05-21T04:45:20.758+0000] {taskinstance.py:2306} INFO - Starting attempt 3 of 3
[2024-05-21T04:45:20.765+0000] {taskinstance.py:2330} INFO - Executing <Task(PythonOperator): transform_load_weather_data> on 2024-05-21 04:41:11.953754+00:00
[2024-05-21T04:45:20.768+0000] {warnings.py:110} WARNING - /home/***/.local/lib/python3.12/site-packages/***/task/task_runner/standard_task_runner.py:61: DeprecationWarning: This process (pid=7734) is multi-threaded, use of fork() may lead to deadlocks in the child.
  pid = os.fork()

[2024-05-21T04:45:20.770+0000] {standard_task_runner.py:63} INFO - Started process 7736 to run task
[2024-05-21T04:45:20.770+0000] {standard_task_runner.py:90} INFO - Running: ['***', 'tasks', 'run', 'weather_dag', 'transform_load_weather_data', 'manual__2024-05-21T04:41:11.953754+00:00', '--job-id', '65', '--raw', '--subdir', 'DAGS_FOLDER/weather_dag.py', '--cfg-path', '/tmp/tmpr8mty5me']
[2024-05-21T04:45:20.771+0000] {standard_task_runner.py:91} INFO - Job 65: Subtask transform_load_weather_data
[2024-05-21T04:45:20.799+0000] {task_command.py:426} INFO - Running <TaskInstance: weather_dag.transform_load_weather_data manual__2024-05-21T04:41:11.953754+00:00 [running]> on host 39024998a807
[2024-05-21T04:45:20.852+0000] {taskinstance.py:2648} INFO - Exporting env vars: AIRFLOW_CTX_DAG_OWNER='***' AIRFLOW_CTX_DAG_ID='weather_dag' AIRFLOW_CTX_TASK_ID='transform_load_weather_data' AIRFLOW_CTX_EXECUTION_DATE='2024-05-21T04:41:11.953754+00:00' AIRFLOW_CTX_TRY_NUMBER='3' AIRFLOW_CTX_DAG_RUN_ID='manual__2024-05-21T04:41:11.953754+00:00'
[2024-05-21T04:45:20.853+0000] {taskinstance.py:430} INFO - ::endgroup::
[2024-05-21T04:45:20.866+0000] {taskinstance.py:441} INFO - ::group::Post task execution logs
[2024-05-21T04:45:20.867+0000] {taskinstance.py:2905} ERROR - Task failed with exception
Traceback (most recent call last):
  File "/home/airflow/.local/lib/python3.12/site-packages/airflow/models/taskinstance.py", line 465, in _execute_task
    result = _execute_callable(context=context, **execute_callable_kwargs)
             ^^^^^^^^^^^^^^^^^^^^^^^^^^^^^^^^^^^^^^^^^^^^^^^^^^^^^^^^^^^^^
  File "/home/airflow/.local/lib/python3.12/site-packages/airflow/models/taskinstance.py", line 432, in _execute_callable
    return execute_callable(context=context, **execute_callable_kwargs)
           ^^^^^^^^^^^^^^^^^^^^^^^^^^^^^^^^^^^^^^^^^^^^^^^^^^^^^^^^^^^^
  File "/home/airflow/.local/lib/python3.12/site-packages/airflow/models/baseoperator.py", line 400, in wrapper
    return func(self, *args, **kwargs)
           ^^^^^^^^^^^^^^^^^^^^^^^^^^^
  File "/home/airflow/.local/lib/python3.12/site-packages/airflow/operators/python.py", line 235, in execute
    return_value = self.execute_callable()
                   ^^^^^^^^^^^^^^^^^^^^^^^
  File "/home/airflow/.local/lib/python3.12/site-packages/airflow/operators/python.py", line 252, in execute_callable
    return self.python_callable(*self.op_args, **self.op_kwargs)
           ^^^^^^^^^^^^^^^^^^^^^^^^^^^^^^^^^^^^^^^^^^^^^^^^^^^^^
  File "/opt/airflow/dags/weather_dag.py", line 52, in transform_load_data
    client = boto3.client('s3', aws_credentials)
                                ^^^^^^^^^^^^^^^
NameError: name 'aws_credentials' is not defined
[2024-05-21T04:45:20.874+0000] {taskinstance.py:1206} INFO - Marking task as FAILED. dag_id=weather_dag, task_id=transform_load_weather_data, run_id=manual__2024-05-21T04:41:11.953754+00:00, execution_date=20240521T044111, start_date=20240521T044520, end_date=20240521T044520
[2024-05-21T04:45:20.881+0000] {standard_task_runner.py:110} ERROR - Failed to execute job 65 for task transform_load_weather_data (name 'aws_credentials' is not defined; 7736)
[2024-05-21T04:45:20.912+0000] {local_task_job_runner.py:240} INFO - Task exited with return code 1
[2024-05-21T04:45:20.921+0000] {taskinstance.py:3498} INFO - 0 downstream tasks scheduled from follow-on schedule check
[2024-05-21T04:45:20.922+0000] {local_task_job_runner.py:222} INFO - ::endgroup::
